Workbook
Name Business_Day_End: '01_Parameters'!$C$14
Name Business_Day_Start: '01_Parameters'!$C$13
Name Duplicate_Amount_Tolerance: '01_Parameters'!$C$15
Name High_Value_AP_Threshold: '01_Parameters'!$C$8
Name High_Value_GL_Threshold: '01_Parameters'!$C$7
Name Invoice_Posting_Review_Limit: '01_Parameters'!$C$19
Name Near_Duplicate_Window: '01_Parameters'!$C$16
Name Reporting_End_Date: '01_Parameters'!$C$6
Name Reporting_Start_Date: '01_Parameters'!$C$5
Name Round_Number_Threshold: '01_Parameters'!$C$17
Name Year_End_Window_End: '01_Parameters'!$C$10
Name Year_End_Window_Start: '01_Parameters'!$C$9

Sheet 00_Read_Me
A1: Audit Data Analytics: General Ledger & Accounts Payable Exception Detection
A2: Namaa Retail Company — شركة نماء للتجزئة | Educational portfolio simulation | Reporting period: 01-Jan-2025 to 31-Dec-2025 | Currency: SAR
A4: Project information | B4: Value
A5: Fictional entity | B5: Namaa Retail Company — شركة نماء للتجزئة
A6: Project type | B6: Educational audit analytics simulation using synthetic financial transaction data
A7: Prepared by | B7: Accounting Student — Educational Portfolio Project.
A8: Preparation date | B8: 22-Oct-2026
A9: Tools used | B9: Microsoft Excel-compatible workbook, Python for deterministic synthetic data generation, PDF memorandum
A11: Project objective | B11: The purpose of this project is to demonstrate how audit data analytics can be used to examine accounting transaction populations, identify unusual patterns, and prioritize transactions for further audit investigation.
A13: Audit analytics workflow | B13: Data preparation → Data validation → Risk-based test design → Exception detection → Exception investigation → Evaluation → Reporting
A15: Worksheet guide | B15: 00_Read_Me: overview and instructions | 01_Parameters: editable thresholds | 02_GL_Data: GL population | 03_AP_Data: AP population | 04_Analytics_Tests: test catalog and results | 05_Exception_Register: traceable flagged items | 06_Dashboard: executive summary | 07_Audit_Memo: memo summary
A16: How to use | B16: 1. Review assumptions. 2. Review synthetic datasets. 3. Inspect test catalog. 4. Review flagged transactions. 5. Record simulated follow-up. 6. Review dashboard and memo.
A18: Important disclaimer | B18: Educational audit analytics simulation using synthetic transaction data. The transactions, counterparties, and exceptions are fictional and do not represent actual records of a real company. An identified anomaly does not, by itself, establish fraud or a financial statement misstatement.
A19: Data limitations | B19: All transactional data are synthetic; this is not an actual audit engagement; tests are illustrative and do not replace professional judgment; real-world completeness and accuracy would need separate assessment; a flag is not automatically an error or evidence of fraud.
... A21: Additional worksheet | B21: 99_Internal_QA is hidden and contains the planted-anomaly validation key and build checks; it is not presented as an audit working paper.

Sheet 01_Parameters
A1: Parameters & Assumptions
A2: Editable screening assumptions. Thresholds are screening rules and are not financial statement materiality.
A4: Parameter_ID | B4: Parameter_Name | C4: Parameter_Value | D4: Unit | E4: Rationale | F4: Source_Type | G4: Last_Updated
A5: P001 | B5: Reporting Start Date | C5: 45658 | D5: Date | E5: Beginning of reporting period | F5: Simulation assumption | G5: 46317
A6: P002 | B6: Reporting End Date | C6: 46022 | D6: Date | E6: End of reporting period | F6: Simulation assumption | G6: 46317
A7: P003 | B7: High-Value GL Threshold | C7: 100000 | D7: SAR | E7: Screen individually large journal lines | F7: Simulation assumption | G7: 46317
A8: P004 | B8: High-Value AP Threshold | C8: 75000 | D8: SAR | E8: Screen large supplier invoices | F8: Simulation assumption | G8: 46317
A9: P005 | B9: Year-End Window Start | C9: 46007 | D9: Date | E9: Illustrative year-end review window | F9: Simulation assumption | G9: 46317
A10: P006 | B10: Year-End Window End | C10: 46022 | D10: Date | E10: End of reporting period | F10: Simulation assumption | G10: 46317
A11: P007 | B11: Weekend Testing | C11: Enabled | D11: Setting | E11: Flag Friday or Saturday postings | F11: Saudi calendar convention | G11: 46317
A12: P008 | B12: After-Hours Testing | C12: Enabled | D12: Setting | E12: Flag timestamps outside business hours | F12: Simulation assumption | G12: 46317
A13: P009 | B13: Business Day Start | C13: 8 | D13: Hour | E13: Normal business hours start | F13: Simulation assumption | G13: 46317
A14: P010 | B14: Business Day End | C14: 18 | D14: Hour | E14: Normal business hours end | F14: Simulation assumption | G14: 46317
A15: P011 | B15: Duplicate Amount Tolerance | C15: 0.01 | D15: SAR | E15: Exact amount comparison tolerance | F15: Simulation assumption | G15: 46317
A16: P012 | B16: Near-Duplicate Window | C16: 90 | D16: Days | E16: Look-back for potentially repeated invoices | F16: Simulation assumption | G16: 46317
A17: P013 | B17: Round-Number Threshold | C17: 10000 | D17: SAR | E17: Minimum amount and multiple for round-number screen | F17: Simulation assumption | G17: 46317
A18: P014 | B18: Reporting Currency | C18: SAR | D18: Currency | E18: All monetary amounts | F18: Simulation assumption | G18: 46317
A19: P015 | B19: Invoice-to-Posting Review Limit | C19: 30 | D19: Days | E19: Flag unusually long invoice-to-posting lag | F19: Simulation assumption | G19: 46317

Sheet 02_GL_Data
A1: 02_GL_Data — Synthetic General Ledger Population
A2: Approximately 500 balanced journal entries and 1,000 lines. Formula-driven screening indicators are in columns V:Z.
A4: Journal_ID | B4: Journal_Line_ID | C4: Posting_Date | D4: Document_Date | E4: Fiscal_Year | F4: Fiscal_Period | G4: Account_Code | H4: Account_Name | I4: Account_Type | J4: Debit | K4: Credit | L4: Signed_Amount | M4: Description | N4: Document_Reference | O4: Source_Module | P4: Created_By | Q4: Approved_By | R4: Creation_Timestamp | S4: Approval_Status | T4: Vendor_ID | U4: Invoice_ID | V4: Is_Year_End | W4: Is_Weekend_Posting | X4: Is_After_Hours | Y4: Is_High_Value | Z4: Is_Round_Number
A5: JE-00001 | B5: JE-00001-01 | C5: 45822 | D5: 45820 | E5: 2025 | F5: 6 | G5: 6600 | H5: Other Operating Expenses | I5: Expense | J5: 169781.06 | K5: 0 | L5: =J5-K5 -> 169781.06 | M5: Manual period adjustment | N5: DOC-00001 | O5: MANUAL_JE | P5: USR_OM | Q5: USR_RE | R5: 45822.802 | S5: Approved | V5: =AND(C5>=Year_End_Window_Start,C5<=Year_End_Window_End) -> FALSE | W5: =AND(OR(WEEKDAY(C5,2)=5,WEEKDAY(C5,2)=6),'01_Parameters'!$C$11="Enabled") -> TRUE | X5: =AND(HOUR(R5)<Business_Day_Start,HOUR(R5)>=0)+AND(HOUR(R5)>=Business_Day_End,HOUR(R5)<=23)>0 -> TRUE | Y5: =ABS(L5)>High_Value_GL_Threshold -> TRUE | Z5: =AND(ABS(L5)>=Round_Number_Threshold,MOD(ABS(L5),Round_Number_Threshold)=0) -> FALSE
A6: JE-00001 | B6: JE-00001-02 | C6: 45822 | D6: 45820 | E6: 2025 | F6: 6 | G6: 2000 | H6: Trade Payables | I6: Liability | J6: 0 | K6: 169781.06 | L6: =J6-K6 -> -169781.06 | M6: Manual period adjustment | N6: DOC-00001 | O6: MANUAL_JE | P6: USR_OM | Q6: USR_RE | R6: 45822.802 | S6: Approved | V6: =AND(C6>=Year_End_Window_Start,C6<=Year_End_Window_End) -> FALSE | W6: =AND(OR(WEEKDAY(C6,2)=5,WEEKDAY(C6,2)=6),'01_Parameters'!$C$11="Enabled") -> TRUE | X6: =AND(HOUR(R6)<Business_Day_Start,HOUR(R6)>=0)+AND(HOUR(R6)>=Business_Day_End,HOUR(R6)<=23)>0 -> TRUE | Y6: =ABS(L6)>High_Value_GL_Threshold -> TRUE | Z6: =AND(ABS(L6)>=Round_Number_Threshold,MOD(ABS(L6),Round_Number_Threshold)=0) -> FALSE
A7: JE-00002 | B7: JE-00002-01 | C7: 45872 | D7: 45869 | E7: 2025 | F7: 8 | G7: 6300 | H7: Marketing Expense | I7: Expense | J7: 47662.32 | K7: 0 | L7: =J7-K7 -> 47662.32 | M7: Manual period adjustment | N7: DOC-00002 | O7: MANUAL_JE | P7: USR_AH | Q7: USR_OM | R7: 45872.417 | S7: Approved | V7: =AND(C7>=Year_End_Window_Start,C7<=Year_End_Window_End) -> FALSE | W7: =AND(OR(WEEKDAY(C7,2)=5,WEEKDAY(C7,2)=6),'01_Parameters'!$C$11="Enabled") -> FALSE | X7: =AND(HOUR(R7)<Business_Day_Start,HOUR(R7)>=0)+AND(HOUR(R7)>=Business_Day_End,HOUR(R7)<=23)>0 -> FALSE | Y7: =ABS(L7)>High_Value_GL_Threshold -> FALSE | Z7: =AND(ABS(L7)>=Round_Number_Threshold,MOD(ABS(L7),Round_Number_Threshold)=0) -> FALSE
A8: JE-00002 | B8: JE-00002-02 | C8: 45872 | D8: 45869 | E8: 2025 | F8: 8 | G8: 2000 | H8: Trade Payables | I8: Liability | J8: 0 | K8: 47662.32 | L8: =J8-K8 -> -47662.32 | M8: Manual period adjustment | N8: DOC-00002 | O8: MANUAL_JE | P8: USR_AH | Q8: USR_OM | R8: 45872.417 | S8: Approved | V8: =AND(C8>=Year_End_Window_Start,C8<=Year_End_Window_End) -> FALSE | W8: =AND(OR(WEEKDAY(C8,2)=5,WEEKDAY(C8,2)=6),'01_Parameters'!$C$11="Enabled") -> FALSE | X8: =AND(HOUR(R8)<Business_Day_Start,HOUR(R8)>=0)+AND(HOUR(R8)>=Business_Day_End,HOUR(R8)<=23)>0 -> FALSE | Y8: =ABS(L8)>High_Value_GL_Threshold -> FALSE | Z8: =AND(ABS(L8)>=Round_Number_Threshold,MOD(ABS(L8),Round_Number_Threshold)=0) -> FALSE
A9: JE-00003 | B9: JE-00003-01 | C9: 45709 | D9: 45704 | E9: 2025 | F9: 2 | G9: 1100 | H9: Trade Receivables | I9: Asset | J9: 46024.42 | K9: 0 | L9: =J9-K9 -> 46024.42 | M9: Daily retail sales | N9: DOC-00003 | O9: AUTO_SALES | P9: USR_SA | Q9: USR_FA | R9: 45709.417 | S9: Approved | V9: =AND(C9>=Year_End_Window_Start,C9<=Year_End_Window_End) -> FALSE | W9: =AND(OR(WEEKDAY(C9,2)=5,WEEKDAY(C9,2)=6),'01_Parameters'!$C$11="Enabled") -> TRUE | X9: =AND(HOUR(R9)<Business_Day_Start,HOUR(R9)>=0)+AND(HOUR(R9)>=Business_Day_End,HOUR(R9)<=23)>0 -> FALSE | Y9: =ABS(L9)>High_Value_GL_Threshold -> FALSE | Z9: =AND(ABS(L9)>=Round_Number_Threshold,MOD(ABS(L9),Round_Number_Threshold)=0) -> FALSE
A10: JE-00003 | B10: JE-00003-02 | C10: 45709 | D10: 45704 | E10: 2025 | F10: 2 | G10: 4000 | H10: Sales Revenue | I10: Revenue | J10: 0 | K10: 46024.42 | L10: =J10-K10 -> -46024.42 | M10: Daily retail sales | N10: DOC-00003 | O10: AUTO_SALES | P10: USR_SA | Q10: USR_FA | R10: 45709.417 | S10: Approved | V10: =AND(C10>=Year_End_Window_Start,C10<=Year_End_Window_End) -> FALSE | W10: =AND(OR(WEEKDAY(C10,2)=5,WEEKDAY(C10,2)=6),'01_Parameters'!$C$11="Enabled") -> TRUE | X10: =AND(HOUR(R10)<Business_Day_Start,HOUR(R10)>=0)+AND(HOUR(R10)>=Business_Day_End,HOUR(R10)<=23)>0 -> FALSE | Y10: =ABS(L10)>High_Value_GL_Threshold -> FALSE | Z10: =AND(ABS(L10)>=Round_Number_Threshold,MOD(ABS(L10),Round_Number_Threshold)=0) -> FALSE
A11: JE-00004 | B11: JE-00004-01 | C11: 45910 | D11: 45905 | E11: 2025 | F11: 9 | G11: 6500 | H11: Depreciation Expense | I11: Expense | J11: 21567.1 | K11: 0 | L11: =J11-K11 -> 21567.1 | M11: Monthly depreciation | N11: DOC-00004 | O11: AUTO_DEPR | P11: USR_FA | Q11: USR_AH | R11: 45910.625 | S11: Approved | V11: =AND(C11>=Year_End_Window_Start,C11<=Year_End_Window_End) -> FALSE | W11: =AND(OR(WEEKDAY(C11,2)=5,WEEKDAY(C11,2)=6),'01_Parameters'!$C$11="Enabled") -> FALSE | X11: =AND(HOUR(R11)<Business_Day_Start,HOUR(R11)>=0)+AND(HOUR(R11)>=Business_Day_End,HOUR(R11)<=23)>0 -> FALSE | Y11: =ABS(L11)>High_Value_GL_Threshold -> FALSE | Z11: =AND(ABS(L11)>=Round_Number_Threshold,MOD(ABS(L11),Round_Number_Threshold)=0) -> FALSE
A12: JE-00004 | B12: JE-00004-02 | C12: 45910 | D12: 45905 | E12: 2025 | F12: 9 | G12: 1500 | H12: Property and Equipment | I12: Asset | J12: 0 | K12: 21567.1 | L12: =J12-K12 -> -21567.1 | M12: Monthly depreciation | N12: DOC-00004 | O12: AUTO_DEPR | P12: USR_FA | Q12: USR_AH | R12: 45910.625 | S12: Approved | V12: =AND(C12>=Year_End_Window_Start,C12<=Year_End_Window_End) -> FALSE | W12: =AND(OR(WEEKDAY(C12,2)=5,WEEKDAY(C12,2)=6),'01_Parameters'!$C$11="Enabled") -> FALSE | X12: =AND(HOUR(R12)<Business_Day_Start,HOUR(R12)>=0)+AND(HOUR(R12)>=Business_Day_End,HOUR(R12)<=23)>0 -> FALSE | Y12: =ABS(L12)>High_Value_GL_Threshold -> FALSE | Z12: =AND(ABS(L12)>=Round_Number_Threshold,MOD(ABS(L12),Round_Number_Threshold)=0) -> FALSE
A13: JE-00005 | B13: JE-00005-01 | C13: 45874 | D13: 45873 | E13: 2025 | F13: 8 | G13: 6500 | H13: Depreciation Expense | I13: Expense | J13: 35129.35 | K13: 0 | L13: =J13-K13 -> 35129.35 | M13: Monthly depreciation | N13: DOC-00005 | O13: AUTO_DEPR | P13: USR_FA | Q13: USR_RE | R13: 45874.719 | S13: Approved | V13: =AND(C13>=Year_End_Window_Start,C13<=Year_End_Window_End) -> FALSE | W13: =AND(OR(WEEKDAY(C13,2)=5,WEEKDAY(C13,2)=6),'01_Parameters'!$C$11="Enabled") -> FALSE | X13: =AND(HOUR(R13)<Business_Day_Start,HOUR(R13)>=0)+AND(HOUR(R13)>=Business_Day_End,HOUR(R13)<=23)>0 -> FALSE | Y13: =ABS(L13)>High_Value_GL_Threshold -> FALSE | Z13: =AND(ABS(L13)>=Round_Number_Threshold,MOD(ABS(L13),Round_Number_Threshold)=0) -> FALSE
A14: JE-00005 | B14: JE-00005-02 | C14: 45874 | D14: 45873 | E14: 2025 | F14: 8 | G14: 1500 | H14: Property and Equipment | I14: Asset | J14: 0 | K14: 35129.35 | L14: =J14-K14 -> -35129.35 | M14: Monthly depreciation | N14: DOC-00005 | O14: AUTO_DEPR | P14: USR_FA | Q14: USR_RE | R14: 45874.719 | S14: Approved | V14: =AND(C14>=Year_End_Window_Start,C14<=Year_End_Window_End) -> FALSE | W14: =AND(OR(WEEKDAY(C14,2)=5,WEEKDAY(C14,2)=6),'01_Parameters'!$C$11="Enabled") -> FALSE | X14: =AND(HOUR(R14)<Business_Day_Start,HOUR(R14)>=0)+AND(HOUR(R14)>=Business_Day_End,HOUR(R14)<=23)>0 -> FALSE | Y14: =ABS(L14)>High_Value_GL_Threshold -> FALSE | Z14: =AND(ABS(L14)>=Round_Number_Threshold,MOD(ABS(L14),Round_Number_Threshold)=0) -> FALSE
A15: JE-00006 | B15: JE-00006-01 | C15: 45750 | D15: 45746 | E15: 2025 | F15: 4 | G15: 6400 | H15: Professional Fees | I15: Expense | J15: 10879.2 | K15: 0 | L15: =J15-K15 -> 10879.2 | M15: Manual period adjustment | N15: DOC-00006 | O15: MANUAL_JE | P15: USR_OM | Q15: USR_NA | R15: 45750.375 | S15: Approved | V15: =AND(C15>=Year_End_Window_Start,C15<=Year_End_Window_End) -> FALSE | W15: =AND(OR(WEEKDAY(C15,2)=5,WEEKDAY(C15,2)=6),'01_Parameters'!$C$11="Enabled") -> FALSE | X15: =AND(HOUR(R15)<Business_Day_Start,HOUR(R15)>=0)+AND(HOUR(R15)>=Business_Day_End,HOUR(R15)<=23)>0 -> FALSE | Y15: =ABS(L15)>High_Value_GL_Threshold -> FALSE | Z15: =AND(ABS(L15)>=Round_Number_Threshold,MOD(ABS(L15),Round_Number_Threshold)=0) -> FALSE
A16: JE-00006 | B16: JE-00006-02 | C16: 45750 | D16: 45746 | E16: 2025 | F16: 4 | G16: 2000 | H16: Trade Payables | I16: Liability | J16: 0 | K16: 10879.2 | L16: =J16-K16 -> -10879.2 | M16: Manual period adjustment | N16: DOC-00006 | O16: MANUAL_JE | P16: USR_OM | Q16: USR_NA | R16: 45750.375 | S16: Approved | V16: =AND(C16>=Year_End_Window_Start,C16<=Year_End_Window_End) -> FALSE | W16: =AND(OR(WEEKDAY(C16,2)=5,WEEKDAY(C16,2)=6),'01_Parameters'!$C$11="Enabled") -> FALSE | X16: =AND(HOUR(R16)<Business_Day_Start,HOUR(R16)>=0)+AND(HOUR(R16)>=Business_Day_End,HOUR(R16)<=23)>0 -> FALSE | Y16: =ABS(L16)>High_Value_GL_Threshold -> FALSE | Z16: =AND(ABS(L16)>=Round_Number_Threshold,MOD(ABS(L16),Round_Number_Threshold)=0) -> FALSE
... A24: JE-00010 | B24: JE-00010-02 | C24: 45919 | D24: 45916 | E24: 2025 | F24: 9 | G24: 1500 | H24: Property and Equipment | I24: Asset | J24: 0 | K24: 30865.18 | L24: =J24-K24 -> -30865.18 | M24: Monthly depreciation | N24: DOC-00010 | O24: AUTO_DEPR | P24: USR_RE | Q24: USR_SA | R24: 45919.792 | S24: Approved | V24: =AND(C24>=Year_End_Window_Start,C24<=Year_End_Window_End) -> FALSE | W24: =AND(OR(WEEKDAY(C24,2)=5,WEEKDAY(C24,2)=6),'01_Parameters'!$C$11="Enabled") -> TRUE | X24: =AND(HOUR(R24)<Business_Day_Start,HOUR(R24)>=0)+AND(HOUR(R24)>=Business_Day_End,HOUR(R24)<=23)>0 -> TRUE | Y24: =ABS(L24)>High_Value_GL_Threshold -> FALSE | Z24: =AND(ABS(L24)>=Round_Number_Threshold,MOD(ABS(L24),Round_Number_Threshold)=0) -> FALSE
A25: JE-00011 | B25: JE-00011-01 | C25: 45661 | D25: 45656 | E25: 2025 | F25: 1 | G25: 6200 | H25: Utilities Expense | I25: Expense | J25: 1910.58 | K25: 0 | L25: =J25-K25 -> 1910.58 | M25: Supplier invoice posting | N25: INV-00011 | O25: AUTO_AP | P25: USR_SA | Q25: USR_AH | R25: 45661.604 | S25: Approved | T25: V010 | U25: INV-00011 | V25: =AND(C25>=Year_End_Window_Start,C25<=Year_End_Window_End) -> FALSE | W25: =AND(OR(WEEKDAY(C25,2)=5,WEEKDAY(C25,2)=6),'01_Parameters'!$C$11="Enabled") -> TRUE | X25: =AND(HOUR(R25)<Business_Day_Start,HOUR(R25)>=0)+AND(HOUR(R25)>=Business_Day_End,HOUR(R25)<=23)>0 -> FALSE | Y25: =ABS(L25)>High_Value_GL_Threshold -> FALSE | Z25: =AND(ABS(L25)>=Round_Number_Threshold,MOD(ABS(L25),Round_Number_Threshold)=0) -> FALSE
A26: JE-00011 | B26: JE-00011-02 | C26: 45661 | D26: 45656 | E26: 2025 | F26: 1 | G26: 2000 | H26: Trade Payables | I26: Liability | J26: 0 | K26: 1910.58 | L26: =J26-K26 -> -1910.58 | M26: Supplier invoice posting | N26: INV-00011 | O26: AUTO_AP | P26: USR_SA | Q26: USR_AH | R26: 45661.604 | S26: Approved | T26: V010 | U26: INV-00011 | V26: =AND(C26>=Year_End_Window_Start,C26<=Year_End_Window_End) -> FALSE | W26: =AND(OR(WEEKDAY(C26,2)=5,WEEKDAY(C26,2)=6),'01_Parameters'!$C$11="Enabled") -> TRUE | X26: =AND(HOUR(R26)<Business_Day_Start,HOUR(R26)>=0)+AND(HOUR(R26)>=Business_Day_End,HOUR(R26)<=23)>0 -> FALSE | Y26: =ABS(L26)>High_Value_GL_Threshold -> FALSE | Z26: =AND(ABS(L26)>=Round_Number_Threshold,MOD(ABS(L26),Round_Number_Threshold)=0) -> FALSE
A27: JE-00012 | B27: JE-00012-01 | C27: 45737 | D27: 45937 | E27: 2025 | F27: 3 | G27: 6000 | H27: Salaries Expense | I27: Expense | J27: 74307.73 | K27: 0 | L27: =J27-K27 -> 74307.73 | M27: Monthly payroll accrual | N27: DOC-00012 | O27: AUTO_PAYROLL | P27: USR_OM | Q27: USR_AH | R27: 45942.812 | S27: Approved | V27: =AND(C27>=Year_End_Window_Start,C27<=Year_End_Window_End) -> FALSE | W27: =AND(OR(WEEKDAY(C27,2)=5,WEEKDAY(C27,2)=6),'01_Parameters'!$C$11="Enabled") -> TRUE | X27: =AND(HOUR(R27)<Business_Day_Start,HOUR(R27)>=0)+AND(HOUR(R27)>=Business_Day_End,HOUR(R27)<=23)>0 -> TRUE | Y27: =ABS(L27)>High_Value_GL_Threshold -> FALSE | Z27: =AND(ABS(L27)>=Round_Number_Threshold,MOD(ABS(L27),Round_Number_Threshold)=0) -> FALSE
A28: JE-00012 | B28: JE-00012-02 | C28: 45737 | D28: 45937 | E28: 2025 | F28: 3 | G28: 2100 | H28: Accrued Expenses | I28: Liability | J28: 0 | K28: 74307.73 | L28: =J28-K28 -> -74307.73 | M28: Monthly payroll accrual | N28: DOC-00012 | O28: AUTO_PAYROLL | P28: USR_OM | Q28: USR_AH | R28: 45942.812 | S28: Approved | V28: =AND(C28>=Year_End_Window_Start,C28<=Year_End_Window_End) -> FALSE | W28: =AND(OR(WEEKDAY(C28,2)=5,WEEKDAY(C28,2)=6),'01_Parameters'!$C$11="Enabled") -> TRUE | X28: =AND(HOUR(R28)<Business_Day_Start,HOUR(R28)>=0)+AND(HOUR(R28)>=Business_Day_End,HOUR(R28)<=23)>0 -> TRUE | Y28: =ABS(L28)>High_Value_GL_Threshold -> FALSE | Z28: =AND(ABS(L28)>=Round_Number_Threshold,MOD(ABS(L28),Round_Number_Threshold)=0) -> FALSE
A29: JE-00013 | B29: JE-00013-01 | C29: 46006 | D29: 46001 | E29: 2025 | F29: 12 | G29: 1100 | H29: Trade Receivables | I29: Asset | J29: 33640.64 | K29: 0 | L29: =J29-K29 -> 33640.64 | M29: Daily retail sales | N29: DOC-00013 | O29: AUTO_SALES | P29: USR_RE | Q29: USR_AH | R29: 45754.979 | S29: Approved | V29: =AND(C29>=Year_End_Window_Start,C29<=Year_End_Window_End) -> FALSE | W29: =AND(OR(WEEKDAY(C29,2)=5,WEEKDAY(C29,2)=6),'01_Parameters'!$C$11="Enabled") -> FALSE | X29: =AND(HOUR(R29)<Business_Day_Start,HOUR(R29)>=0)+AND(HOUR(R29)>=Business_Day_End,HOUR(R29)<=23)>0 -> TRUE | Y29: =ABS(L29)>High_Value_GL_Threshold -> FALSE | Z29: =AND(ABS(L29)>=Round_Number_Threshold,MOD(ABS(L29),Round_Number_Threshold)=0) -> FALSE
A30: JE-00013 | B30: JE-00013-02 | C30: 46006 | D30: 46001 | E30: 2025 | F30: 12 | G30: 4000 | H30: Sales Revenue | I30: Revenue | J30: 0 | K30: 33640.64 | L30: =J30-K30 -> -33640.64 | M30: Daily retail sales | N30: DOC-00013 | O30: AUTO_SALES | P30: USR_RE | Q30: USR_AH | R30: 45754.979 | S30: Approved | V30: =AND(C30>=Year_End_Window_Start,C30<=Year_End_Window_End) -> FALSE | W30: =AND(OR(WEEKDAY(C30,2)=5,WEEKDAY(C30,2)=6),'01_Parameters'!$C$11="Enabled") -> FALSE | X30: =AND(HOUR(R30)<Business_Day_Start,HOUR(R30)>=0)+AND(HOUR(R30)>=Business_Day_End,HOUR(R30)<=23)>0 -> TRUE | Y30: =ABS(L30)>High_Value_GL_Threshold -> FALSE | Z30: =AND(ABS(L30)>=Round_Number_Threshold,MOD(ABS(L30),Round_Number_Threshold)=0) -> FALSE
A31: JE-00014 | B31: JE-00014-01 | C31: 45877 | D31: 45874 | E31: 2025 | F31: 8 | G31: 6000 | H31: Salaries Expense | I31: Expense | J31: 50000 | K31: 0 | L31: =J31-K31 -> 50000 | M31: Monthly payroll accrual | N31: DOC-00014 | O31: AUTO_PAYROLL | P31: USR_RE | Q31: USR_AH | R31: 45877.865 | S31: Approved | V31: =AND(C31>=Year_End_Window_Start,C31<=Year_End_Window_End) -> FALSE | W31: =AND(OR(WEEKDAY(C31,2)=5,WEEKDAY(C31,2)=6),'01_Parameters'!$C$11="Enabled") -> TRUE | X31: =AND(HOUR(R31)<Business_Day_Start,HOUR(R31)>=0)+AND(HOUR(R31)>=Business_Day_End,HOUR(R31)<=23)>0 -> TRUE | Y31: =ABS(L31)>High_Value_GL_Threshold -> FALSE | Z31: =AND(ABS(L31)>=Round_Number_Threshold,MOD(ABS(L31),Round_Number_Threshold)=0) -> TRUE
A32: JE-00014 | B32: JE-00014-02 | C32: 45877 | D32: 45874 | E32: 2025 | F32: 8 | G32: 2100 | H32: Accrued Expenses | I32: Liability | J32: 0 | K32: 50000 | L32: =J32-K32 -> -50000 | M32: Monthly payroll accrual | N32: DOC-00014 | O32: AUTO_PAYROLL | P32: USR_RE | Q32: USR_AH | R32: 45877.865 | S32: Approved | V32: =AND(C32>=Year_End_Window_Start,C32<=Year_End_Window_End) -> FALSE | W32: =AND(OR(WEEKDAY(C32,2)=5,WEEKDAY(C32,2)=6),'01_Parameters'!$C$11="Enabled") -> TRUE | X32: =AND(HOUR(R32)<Business_Day_Start,HOUR(R32)>=0)+AND(HOUR(R32)>=Business_Day_End,HOUR(R32)<=23)>0 -> TRUE | Y32: =ABS(L32)>High_Value_GL_Threshold -> FALSE | Z32: =AND(ABS(L32)>=Round_Number_Threshold,MOD(ABS(L32),Round_Number_Threshold)=0) -> TRUE
A33: JE-00015 | B33: JE-00015-01 | C33: 45935 | D33: 45934 | E33: 2025 | F33: 10 | G33: 6600 | H33: Other Operating Expenses | I33: Expense | J33: 51634.78 | K33: 0 | L33: =J33-K33 -> 51634.78 | M33: Supplier invoice posting | N33: INV-00015 | O33: AUTO_AP | P33: USR_AH | Q33: USR_AH | R33: 45935.26 | S33: Approved | T33: V005 | U33: INV-00015 | V33: =AND(C33>=Year_End_Window_Start,C33<=Year_End_Window_End) -> FALSE | W33: =AND(OR(WEEKDAY(C33,2)=5,WEEKDAY(C33,2)=6),'01_Parameters'!$C$11="Enabled") -> FALSE | X33: =AND(HOUR(R33)<Business_Day_Start,HOUR(R33)>=0)+AND(HOUR(R33)>=Business_Day_End,HOUR(R33)<=23)>0 -> TRUE | Y33: =ABS(L33)>High_Value_GL_Threshold -> FALSE | Z33: =AND(ABS(L33)>=Round_Number_Threshold,MOD(ABS(L33),Round_Number_Threshold)=0) -> FALSE
A34: JE-00015 | B34: JE-00015-02 | C34: 45935 | D34: 45934 | E34: 2025 | F34: 10 | G34: 2000 | H34: Trade Payables | I34: Liability | J34: 0 | K34: 51634.78 | L34: =J34-K34 -> -51634.78 | M34: Supplier invoice posting | N34: INV-00015 | O34: AUTO_AP | P34: USR_AH | Q34: USR_AH | R34: 45935.26 | S34: Approved | T34: V005 | U34: INV-00015 | V34: =AND(C34>=Year_End_Window_Start,C34<=Year_End_Window_End) -> FALSE | W34: =AND(OR(WEEKDAY(C34,2)=5,WEEKDAY(C34,2)=6),'01_Parameters'!$C$11="Enabled") -> FALSE | X34: =AND(HOUR(R34)<Business_Day_Start,HOUR(R34)>=0)+AND(HOUR(R34)>=Business_Day_End,HOUR(R34)<=23)>0 -> TRUE | Y34: =ABS(L34)>High_Value_GL_Threshold -> FALSE | Z34: =AND(ABS(L34)>=Round_Number_Threshold,MOD(ABS(L34),Round_Number_Threshold)=0) -> FALSE
A35: JE-00016 | B35: JE-00016-01 | C35: 45753 | D35: 45753 | E35: 2025 | F35: 4 | G35: 4000 | H35: Sales Revenue | I35: Revenue | J35: 81715.31 | K35: 0 | L35: =J35-K35 -> 81715.31 | M35: Manual revenue to equipment transfer | N35: DOC-00016 | O35: MANUAL_JE | P35: USR_OM | Q35: USR_FA | R35: 45753.417 | S35: Approved | V35: =AND(C35>=Year_End_Window_Start,C35<=Year_End_Window_End) -> FALSE | W35: =AND(OR(WEEKDAY(C35,2)=5,WEEKDAY(C35,2)=6),'01_Parameters'!$C$11="Enabled") -> FALSE | X35: =AND(HOUR(R35)<Business_Day_Start,HOUR(R35)>=0)+AND(HOUR(R35)>=Business_Day_End,HOUR(R35)<=23)>0 -> FALSE | Y35: =ABS(L35)>High_Value_GL_Threshold -> FALSE | Z35: =AND(ABS(L35)>=Round_Number_Threshold,MOD(ABS(L35),Round_Number_Threshold)=0) -> FALSE
A36: JE-00016 | B36: JE-00016-02 | C36: 45753 | D36: 45753 | E36: 2025 | F36: 4 | G36: 1500 | H36: Property and Equipment | I36: Asset | J36: 0 | K36: 81715.31 | L36: =J36-K36 -> -81715.31 | M36: Manual revenue to equipment transfer | N36: DOC-00016 | O36: MANUAL_JE | P36: USR_OM | Q36: USR_FA | R36: 45753.417 | S36: Approved | V36: =AND(C36>=Year_End_Window_Start,C36<=Year_End_Window_End) -> FALSE | W36: =AND(OR(WEEKDAY(C36,2)=5,WEEKDAY(C36,2)=6),'01_Parameters'!$C$11="Enabled") -> FALSE | X36: =AND(HOUR(R36)<Business_Day_Start,HOUR(R36)>=0)+AND(HOUR(R36)>=Business_Day_End,HOUR(R36)<=23)>0 -> FALSE | Y36: =ABS(L36)>High_Value_GL_Threshold -> FALSE | Z36: =AND(ABS(L36)>=Round_Number_Threshold,MOD(ABS(L36),Round_Number_Threshold)=0) -> FALSE
A37: JE-00017 | B37: JE-00017-01 | C37: 45759 | D37: 45758 | E37: 2025 | F37: 4 | G37: 5000 | H37: Cost of Goods Sold | I37: Expense | J37: 84369.11 | K37: 0 | L37: =J37-K37 -> 84369.11 | M37: Inventory movement | N37: DOC-00017 | O37: AUTO_INVENTORY | P37: USR_FA | Q37: USR_OM | R37: 45759.281 | S37: Approved | V37: =AND(C37>=Year_End_Window_Start,C37<=Year_End_Window_End) -> FALSE | W37: =AND(OR(WEEKDAY(C37,2)=5,WEEKDAY(C37,2)=6),'01_Parameters'!$C$11="Enabled") -> TRUE | X37: =AND(HOUR(R37)<Business_Day_Start,HOUR(R37)>=0)+AND(HOUR(R37)>=Business_Day_End,HOUR(R37)<=23)>0 -> TRUE | Y37: =ABS(L37)>High_Value_GL_Threshold -> FALSE | Z37: =AND(ABS(L37)>=Round_Number_Threshold,MOD(ABS(L37),Round_Number_Threshold)=0) -> FALSE
A38: JE-00017 | B38: JE-00017-02 | C38: 45759 | D38: 45758 | E38: 2025 | F38: 4 | G38: 1200 | H38: Inventory | I38: Asset | J38: 0 | K38: 84369.11 | L38: =J38-K38 -> -84369.11 | M38: Inventory movement | N38: DOC-00017 | O38: AUTO_INVENTORY | P38: USR_FA | Q38: USR_OM | R38: 45759.281 | S38: Approved | V38: =AND(C38>=Year_End_Window_Start,C38<=Year_End_Window_End) -> FALSE | W38: =AND(OR(WEEKDAY(C38,2)=5,WEEKDAY(C38,2)=6),'01_Parameters'!$C$11="Enabled") -> TRUE | X38: =AND(HOUR(R38)<Business_Day_Start,HOUR(R38)>=0)+AND(HOUR(R38)>=Business_Day_End,HOUR(R38)<=23)>0 -> TRUE | Y38: =ABS(L38)>High_Value_GL_Threshold -> FALSE | Z38: =AND(ABS(L38)>=Round_Number_Threshold,MOD(ABS(L38),Round_Number_Threshold)=0) -> FALSE
A39: JE-00018 | B39: JE-00018-01 | C39: 45802 | D39: 45802 | E39: 2025 | F39: 5 | G39: 6300 | H39: Marketing Expense | I39: Expense | J39: 138757.1 | K39: 0 | L39: =J39-K39 -> 138757.1 | M39: Manual period adjustment | N39: DOC-00018 | O39: MANUAL_JE | P39: USR_NA | Q39: USR_AH | R39: 45802.385 | S39: Approved | V39: =AND(C39>=Year_End_Window_Start,C39<=Year_End_Window_End) -> FALSE | W39: =AND(OR(WEEKDAY(C39,2)=5,WEEKDAY(C39,2)=6),'01_Parameters'!$C$11="Enabled") -> FALSE | X39: =AND(HOUR(R39)<Business_Day_Start,HOUR(R39)>=0)+AND(HOUR(R39)>=Business_Day_End,HOUR(R39)<=23)>0 -> FALSE | Y39: =ABS(L39)>High_Value_GL_Threshold -> TRUE | Z39: =AND(ABS(L39)>=Round_Number_Threshold,MOD(ABS(L39),Round_Number_Threshold)=0) -> FALSE
A40: JE-00018 | B40: JE-00018-02 | C40: 45802 | D40: 45802 | E40: 2025 | F40: 5 | G40: 2000 | H40: Trade Payables | I40: Liability | J40: 0 | K40: 138757.1 | L40: =J40-K40 -> -138757.1 | M40: Manual period adjustment | N40: DOC-00018 | O40: MANUAL_JE | P40: USR_NA | Q40: USR_AH | R40: 45802.385 | S40: Approved | V40: =AND(C40>=Year_End_Window_Start,C40<=Year_End_Window_End) -> FALSE | W40: =AND(OR(WEEKDAY(C40,2)=5,WEEKDAY(C40,2)=6),'01_Parameters'!$C$11="Enabled") -> FALSE | X40: =AND(HOUR(R40)<Business_Day_Start,HOUR(R40)>=0)+AND(HOUR(R40)>=Business_Day_End,HOUR(R40)<=23)>0 -> FALSE | Y40: =ABS(L40)>High_Value_GL_Threshold -> TRUE | Z40: =AND(ABS(L40)>=Round_Number_Threshold,MOD(ABS(L40),Round_Number_Threshold)=0) -> FALSE
A41: JE-00019 | B41: JE-00019-01 | C41: 45865 | D41: 45862 | E41: 2025 | F41: 7 | G41: 5000 | H41: Cost of Goods Sold | I41: Expense | J41: 13387.2 | K41: 0 | L41: =J41-K41 -> 13387.2 | M41: Inventory movement | N41: DOC-00019 | O41: AUTO_INVENTORY | P41: USR_NA | Q41: USR_AH | R41: 45865.729 | S41: Approved | V41: =AND(C41>=Year_End_Window_Start,C41<=Year_End_Window_End) -> FALSE | W41: =AND(OR(WEEKDAY(C41,2)=5,WEEKDAY(C41,2)=6),'01_Parameters'!$C$11="Enabled") -> FALSE | X41: =AND(HOUR(R41)<Business_Day_Start,HOUR(R41)>=0)+AND(HOUR(R41)>=Business_Day_End,HOUR(R41)<=23)>0 -> FALSE | Y41: =ABS(L41)>High_Value_GL_Threshold -> FALSE | Z41: =AND(ABS(L41)>=Round_Number_Threshold,MOD(ABS(L41),Round_Number_Threshold)=0) -> FALSE
A42: JE-00019 | B42: JE-00019-02 | C42: 45865 | D42: 45862 | E42: 2025 | F42: 7 | G42: 1200 | H42: Inventory | I42: Asset | J42: 0 | K42: 13387.2 | L42: =J42-K42 -> -13387.2 | M42: Inventory movement | N42: DOC-00019 | O42: AUTO_INVENTORY | P42: USR_NA | Q42: USR_AH | R42: 45865.729 | S42: Approved | V42: =AND(C42>=Year_End_Window_Start,C42<=Year_End_Window_End) -> FALSE | W42: =AND(OR(WEEKDAY(C42,2)=5,WEEKDAY(C42,2)=6),'01_Parameters'!$C$11="Enabled") -> FALSE | X42: =AND(HOUR(R42)<Business_Day_Start,HOUR(R42)>=0)+AND(HOUR(R42)>=Business_Day_End,HOUR(R42)<=23)>0 -> FALSE | Y42: =ABS(L42)>High_Value_GL_Threshold -> FALSE | Z42: =AND(ABS(L42)>=Round_Number_Threshold,MOD(ABS(L42),Round_Number_Threshold)=0) -> FALSE
A43: JE-00020 | B43: JE-00020-01 | C43: 45848 | D43: 45848 | E43: 2025 | F43: 7 | G43: 6600 | H43: Other Operating Expenses | I43: Expense | J43: 78012.15 | K43: 0 | L43: =J43-K43 -> 78012.15 | M43: Supplier invoice posting | N43: INV-00020 | O43: AUTO_AP | P43: USR_RE | Q43: USR_AH | R43: 45848.781 | S43: Approved | T43: V004 | U43: INV-00020 | V43: =AND(C43>=Year_End_Window_Start,C43<=Year_End_Window_End) -> FALSE | W43: =AND(OR(WEEKDAY(C43,2)=5,WEEKDAY(C43,2)=6),'01_Parameters'!$C$11="Enabled") -> FALSE | X43: =AND(HOUR(R43)<Business_Day_Start,HOUR(R43)>=0)+AND(HOUR(R43)>=Business_Day_End,HOUR(R43)<=23)>0 -> TRUE | Y43: =ABS(L43)>High_Value_GL_Threshold -> FALSE | Z43: =AND(ABS(L43)>=Round_Number_Threshold,MOD(ABS(L43),Round_Number_Threshold)=0) -> FALSE
A44: JE-00020 | B44: JE-00020-02 | C44: 45848 | D44: 45848 | E44: 2025 | F44: 7 | G44: 2000 | H44: Trade Payables | I44: Liability | J44: 0 | K44: 78012.15 | L44: =J44-K44 -> -78012.15 | M44: Supplier invoice posting | N44: INV-00020 | O44: AUTO_AP | P44: USR_RE | Q44: USR_AH | R44: 45848.781 | S44: Approved | T44: V004 | U44: INV-00020 | V44: =AND(C44>=Year_End_Window_Start,C44<=Year_End_Window_End) -> FALSE | W44: =AND(OR(WEEKDAY(C44,2)=5,WEEKDAY(C44,2)=6),'01_Parameters'!$C$11="Enabled") -> FALSE | X44: =AND(HOUR(R44)<Business_Day_Start,HOUR(R44)>=0)+AND(HOUR(R44)>=Business_Day_End,HOUR(R44)<=23)>0 -> TRUE | Y44: =ABS(L44)>High_Value_GL_Threshold -> FALSE | Z44: =AND(ABS(L44)>=Round_Number_Threshold,MOD(ABS(L44),Round_Number_Threshold)=0) -> FALSE
A45: JE-00021 | B45: JE-00021-01 | C45: 45914 | D45: 45910 | E45: 2025 | F45: 9 | G45: 6500 | H45: Depreciation Expense | I45: Expense | J45: 70546.03 | K45: 0 | L45: =J45-K45 -> 70546.03 | M45: Monthly depreciation | N45: DOC-00021 | O45: AUTO_DEPR | P45: USR_NA | Q45: USR_OM | R45: 45914.594 | S45: Approved | V45: =AND(C45>=Year_End_Window_Start,C45<=Year_End_Window_End) -> FALSE | W45: =AND(OR(WEEKDAY(C45,2)=5,WEEKDAY(C45,2)=6),'01_Parameters'!$C$11="Enabled") -> FALSE | X45: =AND(HOUR(R45)<Business_Day_Start,HOUR(R45)>=0)+AND(HOUR(R45)>=Business_Day_End,HOUR(R45)<=23)>0 -> FALSE | Y45: =ABS(L45)>High_Value_GL_Threshold -> FALSE | Z45: =AND(ABS(L45)>=Round_Number_Threshold,MOD(ABS(L45),Round_Number_Threshold)=0) -> FALSE
A46: JE-00021 | B46: JE-00021-02 | C46: 45914 | D46: 45910 | E46: 2025 | F46: 9 | G46: 1500 | H46: Property and Equipment | I46: Asset | J46: 0 | K46: 70546.03 | L46: =J46-K46 -> -70546.03 | M46: Monthly depreciation | N46: DOC-00021 | O46: AUTO_DEPR | P46: USR_NA | Q46: USR_OM | R46: 45914.594 | S46: Approved | V46: =AND(C46>=Year_End_Window_Start,C46<=Year_End_Window_End) -> FALSE | W46: =AND(OR(WEEKDAY(C46,2)=5,WEEKDAY(C46,2)=6),'01_Parameters'!$C$11="Enabled") -> FALSE | X46: =AND(HOUR(R46)<Business_Day_Start,HOUR(R46)>=0)+AND(HOUR(R46)>=Business_Day_End,HOUR(R46)<=23)>0 -> FALSE | Y46: =ABS(L46)>High_Value_GL_Threshold -> FALSE | Z46: =AND(ABS(L46)>=Round_Number_Threshold,MOD(ABS(L46),Round_Number_Threshold)=0) -> FALSE
A47: JE-00022 | B47: JE-00022-01 | C47: 45909 | D47: 45906 | E47: 2025 | F47: 9 | G47: 6000 | H47: Salaries Expense | I47: Expense | J47: 56483.11 | K47: 0 | L47: =J47-K47 -> 56483.11 | M47: Monthly payroll accrual | N47: DOC-00022 | O47: AUTO_PAYROLL | P47: USR_OM | Q47: USR_SA | R47: 45909.458 | S47: Approved | V47: =AND(C47>=Year_End_Window_Start,C47<=Year_End_Window_End) -> FALSE | W47: =AND(OR(WEEKDAY(C47,2)=5,WEEKDAY(C47,2)=6),'01_Parameters'!$C$11="Enabled") -> FALSE | X47: =AND(HOUR(R47)<Business_Day_Start,HOUR(R47)>=0)+AND(HOUR(R47)>=Business_Day_End,HOUR(R47)<=23)>0 -> FALSE | Y47: =ABS(L47)>High_Value_GL_Threshold -> FALSE | Z47: =AND(ABS(L47)>=Round_Number_Threshold,MOD(ABS(L47),Round_Number_Threshold)=0) -> FALSE
A48: JE-00022 | B48: JE-00022-02 | C48: 45909 | D48: 45906 | E48: 2025 | F48: 9 | G48: 2100 | H48: Accrued Expenses | I48: Liability | J48: 0 | K48: 56483.11 | L48: =J48-K48 -> -56483.11 | M48: Monthly payroll accrual | N48: DOC-00022 | O48: AUTO_PAYROLL | P48: USR_OM | Q48: USR_SA | R48: 45909.458 | S48: Approved | V48: =AND(C48>=Year_End_Window_Start,C48<=Year_End_Window_End) -> FALSE | W48: =AND(OR(WEEKDAY(C48,2)=5,WEEKDAY(C48,2)=6),'01_Parameters'!$C$11="Enabled") -> FALSE | X48: =AND(HOUR(R48)<Business_Day_Start,HOUR(R48)>=0)+AND(HOUR(R48)>=Business_Day_End,HOUR(R48)<=23)>0 -> FALSE | Y48: =ABS(L48)>High_Value_GL_Threshold -> FALSE | Z48: =AND(ABS(L48)>=Round_Number_Threshold,MOD(ABS(L48),Round_Number_Threshold)=0) -> FALSE
...

Sheet 03_AP_Data
A1: 03_AP_Data — Synthetic Accounts Payable Population
A2: Approximately 300 fictional supplier invoices. Amount convention: Gross = Net + VAT (illustrative 15% VAT).
A4: Invoice_ID | B4: Vendor_ID | C4: Vendor_Name | D4: Vendor_Invoice_Number | E4: Invoice_Date | F4: Posting_Date | G4: Due_Date | H4: Gross_Amount | I4: VAT_Amount | J4: Net_Amount | K4: Purchase_Order_ID | L4: Goods_Receipt_ID | M4: Payment_Reference | N4: Payment_Date | O4: Payment_Status | P4: Invoice_Description | Q4: Entered_By | R4: Approved_By | S4: Approval_Status | T4: Supporting_Document_Status | U4: Days_Invoice_to_Posting | V4: Is_High_Value | W4: Is_Potential_Duplicate | X4: Is_Missing_PO | Y4: Is_Missing_Receipt | Z4: Is_Potential_Cutoff | AA4: Exception_Notes
A5: INV-00001 | B5: V009 | C5: Afaq Professional Services | D5: 009-2025-0001 | E5: 45700 | F5: 45715 | G5: 45745 | H5: 70828.4 | I5: 9238.49 | J5: 61589.91 | K5: PO-00001 | M5: PAY-00001 | N5: 45756 | O5: Paid | P5: Utility service | Q5: USR_FA | R5: USR_FA | S5: Approved | T5: Partial | U5: =F5-E5 -> 15 | V5: =H5>High_Value_AP_Threshold -> FALSE | W5: =COUNTIFS($B$5:$B$304,B5,$D$5:$D$304,D5)>1 -> FALSE | X5: =AND(K5="",P5<>"Utility service",P5<>"Campaign services") -> FALSE | Y5: =AND(L5="",OR(P5="Merchandise replenishment",P5="Office supplies",P5="Transport and logistics")) -> FALSE | Z5: =OR(F5>Year_End_Window_End,AND(E5>=Year_End_Window_Start,F5>=Year_End_Window_Start)) -> FALSE
A6: INV-00002 | B6: V002 | C6: Red Sand Facilities LLC | D6: 002-2025-0002 | E6: 45680 | F6: 45681 | G6: 45711 | H6: 57567.48 | I6: 7508.8 | J6: 50058.68 | K6: PO-00002 | M6: PAY-00002 | N6: 45725 | O6: Paid | P6: Campaign services | Q6: USR_AH | R6: USR_SA | S6: Approved | T6: Partial | U6: =F6-E6 -> 1 | V6: =H6>High_Value_AP_Threshold -> FALSE | W6: =COUNTIFS($B$5:$B$304,B6,$D$5:$D$304,D6)>1 -> FALSE | X6: =AND(K6="",P6<>"Utility service",P6<>"Campaign services") -> FALSE | Y6: =AND(L6="",OR(P6="Merchandise replenishment",P6="Office supplies",P6="Transport and logistics")) -> FALSE | Z6: =OR(F6>Year_End_Window_End,AND(E6>=Year_End_Window_Start,F6>=Year_End_Window_Start)) -> FALSE
A7: INV-00003 | B7: V004 | C7: Wadi Marketing Studio | D7: 004-2025-0003 | E7: 45754 | F7: 45754 | G7: 45784 | H7: 53208.61 | I7: 6940.25 | J7: 46268.36 | K7: PO-00003 | L7: GR-00003 | M7: PAY-00003 | N7: 45788 | O7: Paid | P7: Transport and logistics | Q7: USR_NA | R7: USR_SA | S7: Approved | T7: Complete | U7: =F7-E7 -> 0 | V7: =H7>High_Value_AP_Threshold -> FALSE | W7: =COUNTIFS($B$5:$B$304,B7,$D$5:$D$304,D7)>1 -> FALSE | X7: =AND(K7="",P7<>"Utility service",P7<>"Campaign services") -> FALSE | Y7: =AND(L7="",OR(P7="Merchandise replenishment",P7="Office supplies",P7="Transport and logistics")) -> FALSE | Z7: =OR(F7>Year_End_Window_End,AND(E7>=Year_End_Window_Start,F7>=Year_End_Window_Start)) -> FALSE
A8: INV-00004 | B8: V010 | C8: Thuraya Packaging | D8: 010-2025-0004 | E8: 45714 | F8: 45744 | G8: 45774 | H8: 15545.94 | I8: 2027.73 | J8: 13518.21 | K8: PO-00004 | L8: GR-00004 | M8: PAY-00004 | N8: 45756 | O8: Paid | P8: Merchandise replenishment | Q8: USR_FA | R8: USR_SA | S8: Approved | T8: Complete | U8: =F8-E8 -> 30 | V8: =H8>High_Value_AP_Threshold -> FALSE | W8: =COUNTIFS($B$5:$B$304,B8,$D$5:$D$304,D8)>1 -> FALSE | X8: =AND(K8="",P8<>"Utility service",P8<>"Campaign services") -> FALSE | Y8: =AND(L8="",OR(P8="Merchandise replenishment",P8="Office supplies",P8="Transport and logistics")) -> FALSE | Z8: =OR(F8>Year_End_Window_End,AND(E8>=Year_End_Window_Start,F8>=Year_End_Window_Start)) -> FALSE
A9: INV-00005 | B9: V002 | C9: Red Sand Facilities LLC | D9: 002-2025-0005 | E9: 45958 | F9: 45973 | G9: 46003 | H9: 57408.59 | I9: 7488.08 | J9: 49920.51 | K9: PO-00005 | M9: PAY-00005 | N9: 45998 | O9: Paid | P9: Campaign services | Q9: USR_RE | R9: USR_RE | S9: Approved | T9: Partial | U9: =F9-E9 -> 15 | V9: =H9>High_Value_AP_Threshold -> FALSE | W9: =COUNTIFS($B$5:$B$304,B9,$D$5:$D$304,D9)>1 -> FALSE | X9: =AND(K9="",P9<>"Utility service",P9<>"Campaign services") -> FALSE | Y9: =AND(L9="",OR(P9="Merchandise replenishment",P9="Office supplies",P9="Transport and logistics")) -> FALSE | Z9: =OR(F9>Year_End_Window_End,AND(E9>=Year_End_Window_Start,F9>=Year_End_Window_Start)) -> FALSE
A10: INV-00006 | B10: V008 | C10: Desert Star Maintenance | D10: 008-2025-0006 | E10: 45862 | F10: 45863 | G10: 45893 | H10: 56810.71 | I10: 7410.09 | J10: 49400.62 | K10: PO-00006 | M10: PAY-00006 | N10: 45889 | O10: Paid | P10: Utility service | Q10: USR_RE | R10: USR_NA | S10: Approved | T10: Partial | U10: =F10-E10 -> 1 | V10: =H10>High_Value_AP_Threshold -> FALSE | W10: =COUNTIFS($B$5:$B$304,B10,$D$5:$D$304,D10)>1 -> FALSE | X10: =AND(K10="",P10<>"Utility service",P10<>"Campaign services") -> FALSE | Y10: =AND(L10="",OR(P10="Merchandise replenishment",P10="Office supplies",P10="Transport and logistics")) -> FALSE | Z10: =OR(F10>Year_End_Window_End,AND(E10>=Year_End_Window_Start,F10>=Year_End_Window_Start)) -> FALSE
A11: INV-00007 | B11: V009 | C11: Afaq Professional Services | D11: 009-2025-0007 | E11: 45929 | F11: 45934 | G11: 45964 | H11: 12800.93 | I11: 1669.69 | J11: 11131.24 | K11: PO-00007 | O11: Pending | P11: Cloud support services | Q11: USR_NA | R11: USR_OM | S11: Approved | T11: Partial | U11: =F11-E11 -> 5 | V11: =H11>High_Value_AP_Threshold -> FALSE | W11: =COUNTIFS($B$5:$B$304,B11,$D$5:$D$304,D11)>1 -> FALSE | X11: =AND(K11="",P11<>"Utility service",P11<>"Campaign services") -> FALSE | Y11: =AND(L11="",OR(P11="Merchandise replenishment",P11="Office supplies",P11="Transport and logistics")) -> FALSE | Z11: =OR(F11>Year_End_Window_End,AND(E11>=Year_End_Window_Start,F11>=Year_End_Window_Start)) -> FALSE
A12: INV-00008 | B12: V003 | C12: Sahab IT Services | D12: 003-2025-0008 | E12: 45999 | F12: 46004 | G12: 46034 | H12: 41203.64 | I12: 5374.39 | J12: 35829.25 | K12: PO-00008 | M12: PAY-00008 | N12: 46009 | O12: Paid | P12: Utility service | Q12: USR_NA | R12: USR_SA | S12: Approved | T12: Partial | U12: =F12-E12 -> 5 | V12: =H12>High_Value_AP_Threshold -> FALSE | W12: =COUNTIFS($B$5:$B$304,B12,$D$5:$D$304,D12)>1 -> FALSE | X12: =AND(K12="",P12<>"Utility service",P12<>"Campaign services") -> FALSE | Y12: =AND(L12="",OR(P12="Merchandise replenishment",P12="Office supplies",P12="Transport and logistics")) -> FALSE | Z12: =OR(F12>Year_End_Window_End,AND(E12>=Year_End_Window_Start,F12>=Year_End_Window_Start)) -> FALSE
A13: INV-00009 | B13: V010 | C13: Thuraya Packaging | D13: 010-2025-0009 | E13: 45934 | F13: 45964 | G13: 45994 | H13: 43093.15 | I13: 5620.85 | J13: 37472.3 | O13: Pending | P13: Utility service | Q13: USR_RE | R13: USR_NA | S13: Approved | T13: Missing | U13: =F13-E13 -> 30 | V13: =H13>High_Value_AP_Threshold -> FALSE | W13: =COUNTIFS($B$5:$B$304,B13,$D$5:$D$304,D13)>1 -> FALSE | X13: =AND(K13="",P13<>"Utility service",P13<>"Campaign services") -> FALSE | Y13: =AND(L13="",OR(P13="Merchandise replenishment",P13="Office supplies",P13="Transport and logistics")) -> FALSE | Z13: =OR(F13>Year_End_Window_End,AND(E13>=Year_End_Window_Start,F13>=Year_End_Window_Start)) -> FALSE
A14: INV-00010 | B14: V001 | C14: Najd Merchandising Co. | D14: 001-2025-0010 | E14: 45916 | F14: 45926 | G14: 45956 | H14: 51669.22 | I14: 6739.46 | J14: 44929.76 | K14: PO-00010 | M14: PAY-00010 | N14: 45944 | O14: Paid | P14: Store maintenance | Q14: USR_FA | R14: USR_NA | S14: Approved | T14: Partial | U14: =F14-E14 -> 10 | V14: =H14>High_Value_AP_Threshold -> FALSE | W14: =COUNTIFS($B$5:$B$304,B14,$D$5:$D$304,D14)>1 -> FALSE | X14: =AND(K14="",P14<>"Utility service",P14<>"Campaign services") -> FALSE | Y14: =AND(L14="",OR(P14="Merchandise replenishment",P14="Office supplies",P14="Transport and logistics")) -> FALSE | Z14: =OR(F14>Year_End_Window_End,AND(E14>=Year_End_Window_Start,F14>=Year_End_Window_Start)) -> FALSE
A15: INV-00011 | B15: V010 | C15: Thuraya Packaging | D15: 010-2025-0011 | E15: 45735 | F15: 45740 | G15: 45770 | H15: 38578.42 | I15: 5031.97 | J15: 33546.45 | K15: PO-00011 | L15: GR-00011 | M15: PAY-00011 | N15: 45754 | O15: Paid | P15: Merchandise replenishment | Q15: USR_FA | R15: USR_NA | S15: Approved | T15: Complete | U15: =F15-E15 -> 5 | V15: =H15>High_Value_AP_Threshold -> FALSE | W15: =COUNTIFS($B$5:$B$304,B15,$D$5:$D$304,D15)>1 -> FALSE | X15: =AND(K15="",P15<>"Utility service",P15<>"Campaign services") -> FALSE | Y15: =AND(L15="",OR(P15="Merchandise replenishment",P15="Office supplies",P15="Transport and logistics")) -> FALSE | Z15: =OR(F15>Year_End_Window_End,AND(E15>=Year_End_Window_Start,F15>=Year_End_Window_Start)) -> FALSE
A16: INV-00012 | B16: V005 | C16: Rimal Utilities Provider | D16: 005-2025-0012 | E16: 46007 | F16: 46009 | G16: 46039 | H16: 54819.71 | I16: 7150.4 | J16: 47669.31 | K16: PO-00012 | O16: Pending | P16: Cloud support services | Q16: USR_FA | R16: USR_RE | S16: Approved | T16: Partial | U16: =F16-E16 -> 2 | V16: =H16>High_Value_AP_Threshold -> FALSE | W16: =COUNTIFS($B$5:$B$304,B16,$D$5:$D$304,D16)>1 -> FALSE | X16: =AND(K16="",P16<>"Utility service",P16<>"Campaign services") -> FALSE | Y16: =AND(L16="",OR(P16="Merchandise replenishment",P16="Office supplies",P16="Transport and logistics")) -> FALSE | Z16: =OR(F16>Year_End_Window_End,AND(E16>=Year_End_Window_Start,F16>=Year_End_Window_Start)) -> TRUE
A17: INV-00013 | B17: V004 | C17: Wadi Marketing Studio | D17: 004-2025-0013 | E17: 45967 | F17: 45982 | G17: 46012 | H17: 59402.32 | I17: 7748.13 | J17: 51654.19 | K17: PO-00013 | L17: GR-00013 | M17: PAY-00013 | N17: 46002 | O17: Paid | P17: Merchandise replenishment | Q17: USR_SA | R17: USR_RE | S17: Approved | T17: Complete | U17: =F17-E17 -> 15 | V17: =H17>High_Value_AP_Threshold -> FALSE | W17: =COUNTIFS($B$5:$B$304,B17,$D$5:$D$304,D17)>1 -> TRUE | X17: =AND(K17="",P17<>"Utility service",P17<>"Campaign services") -> FALSE | Y17: =AND(L17="",OR(P17="Merchandise replenishment",P17="Office supplies",P17="Transport and logistics")) -> FALSE | Z17: =OR(F17>Year_End_Window_End,AND(E17>=Year_End_Window_Start,F17>=Year_End_Window_Start)) -> FALSE
A18: INV-00014 | B18: V010 | C18: Thuraya Packaging | D18: 010-2025-0014 | E18: 45943 | F18: 45946 | G18: 45976 | H18: 1655.11 | I18: 215.88 | J18: 1439.23 | K18: PO-00014 | L18: GR-00014 | O18: Pending | P18: Transport and logistics | Q18: USR_NA | R18: USR_SA | S18: Approved | T18: Complete | U18: =F18-E18 -> 3 | V18: =H18>High_Value_AP_Threshold -> FALSE | W18: =COUNTIFS($B$5:$B$304,B18,$D$5:$D$304,D18)>1 -> FALSE | X18: =AND(K18="",P18<>"Utility service",P18<>"Campaign services") -> FALSE | Y18: =AND(L18="",OR(P18="Merchandise replenishment",P18="Office supplies",P18="Transport and logistics")) -> FALSE | Z18: =OR(F18>Year_End_Window_End,AND(E18>=Year_End_Window_Start,F18>=Year_End_Window_Start)) -> FALSE
A19: INV-00015 | B19: V005 | C19: Rimal Utilities Provider | D19: 005-2025-0015 | E19: 45692 | F19: 45694 | G19: 45724 | H19: 23627.53 | I19: 3081.85 | J19: 20545.68 | K19: PO-00015 | M19: PAY-00015 | N19: 45738 | O19: Paid | P19: Utility service | Q19: USR_RE | R19: USR_RE | S19: Approved | T19: Partial | U19: =F19-E19 -> 2 | V19: =H19>High_Value_AP_Threshold -> FALSE | W19: =COUNTIFS($B$5:$B$304,B19,$D$5:$D$304,D19)>1 -> FALSE | X19: =AND(K19="",P19<>"Utility service",P19<>"Campaign services") -> FALSE | Y19: =AND(L19="",OR(P19="Merchandise replenishment",P19="Office supplies",P19="Transport and logistics")) -> FALSE | Z19: =OR(F19>Year_End_Window_End,AND(E19>=Year_End_Window_Start,F19>=Year_End_Window_Start)) -> FALSE
A20: INV-00016 | B20: V002 | C20: Red Sand Facilities LLC | D20: 002-2025-0016 | E20: 45979 | F20: 45982 | G20: 46012 | H20: 72049.13 | I20: 9397.71 | J20: 62651.42 | K20: PO-00016 | M20: PAY-00016 | N20: 46008 | O20: Paid | P20: Utility service | Q20: USR_FA | R20: USR_NA | S20: Approved | T20: Partial | U20: =F20-E20 -> 3 | V20: =H20>High_Value_AP_Threshold -> FALSE | W20: =COUNTIFS($B$5:$B$304,B20,$D$5:$D$304,D20)>1 -> FALSE | X20: =AND(K20="",P20<>"Utility service",P20<>"Campaign services") -> FALSE | Y20: =AND(L20="",OR(P20="Merchandise replenishment",P20="Office supplies",P20="Transport and logistics")) -> FALSE | Z20: =OR(F20>Year_End_Window_End,AND(E20>=Year_End_Window_Start,F20>=Year_End_Window_Start)) -> FALSE
A21: INV-00017 | B21: V003 | C21: Sahab IT Services | D21: 003-2025-0017 | E21: 46015 | F21: 46022 | G21: 46052 | H21: 47176.61 | I21: 6153.47 | J21: 41023.14 | K21: PO-00017 | L21: GR-00017 | O21: Pending | P21: Merchandise replenishment | Q21: USR_RE | R21: USR_FA | S21: Approved | T21: Complete | U21: =F21-E21 -> 7 | V21: =H21>High_Value_AP_Threshold -> FALSE | W21: =COUNTIFS($B$5:$B$304,B21,$D$5:$D$304,D21)>1 -> FALSE | X21: =AND(K21="",P21<>"Utility service",P21<>"Campaign services") -> FALSE | Y21: =AND(L21="",OR(P21="Merchandise replenishment",P21="Office supplies",P21="Transport and logistics")) -> FALSE | Z21: =OR(F21>Year_End_Window_End,AND(E21>=Year_End_Window_Start,F21>=Year_End_Window_Start)) -> TRUE
A22: INV-00018 | B22: V001 | C22: Najd Merchandising Co. | D22: 001-2025-0018 | E22: 45957 | F22: 45958 | G22: 45988 | H22: 60673.25 | I22: 7913.9 | J22: 52759.35 | K22: PO-00018 | O22: Pending | P22: Utility service | Q22: USR_NA | R22: USR_NA | S22: Approved | T22: Partial | U22: =F22-E22 -> 1 | V22: =H22>High_Value_AP_Threshold -> FALSE | W22: =COUNTIFS($B$5:$B$304,B22,$D$5:$D$304,D22)>1 -> FALSE | X22: =AND(K22="",P22<>"Utility service",P22<>"Campaign services") -> FALSE | Y22: =AND(L22="",OR(P22="Merchandise replenishment",P22="Office supplies",P22="Transport and logistics")) -> FALSE | Z22: =OR(F22>Year_End_Window_End,AND(E22>=Year_End_Window_Start,F22>=Year_End_Window_Start)) -> FALSE
A23: INV-00019 | B23: V010 | C23: Thuraya Packaging | D23: 010-2025-0019 | E23: 45795 | F23: 45798 | G23: 45828 | H23: 48155.48 | I23: 6281.15 | J23: 41874.33 | K23: PO-00019 | L23: GR-00019 | M23: PAY-00019 | N23: 45821 | O23: Paid | P23: Office supplies | Q23: USR_RE | R23: USR_OM | S23: Approved | T23: Complete | U23: =F23-E23 -> 3 | V23: =H23>High_Value_AP_Threshold -> FALSE | W23: =COUNTIFS($B$5:$B$304,B23,$D$5:$D$304,D23)>1 -> FALSE | X23: =AND(K23="",P23<>"Utility service",P23<>"Campaign services") -> FALSE | Y23: =AND(L23="",OR(P23="Merchandise replenishment",P23="Office supplies",P23="Transport and logistics")) -> FALSE | Z23: =OR(F23>Year_End_Window_End,AND(E23>=Year_End_Window_Start,F23>=Year_End_Window_Start)) -> FALSE
A24: INV-00020 | B24: V004 | C24: Wadi Marketing Studio | D24: 004-2025-0020 | E24: 45799 | F24: 45814 | G24: 45844 | H24: 47072.93 | I24: 6139.95 | J24: 40932.98 | K24: PO-00020 | L24: GR-00020 | M24: PAY-00020 | N24: 45841 | O24: Paid | P24: Office supplies | Q24: USR_AH | R24: USR_SA | S24: Approved | T24: Complete | U24: =F24-E24 -> 15 | V24: =H24>High_Value_AP_Threshold -> FALSE | W24: =COUNTIFS($B$5:$B$304,B24,$D$5:$D$304,D24)>1 -> FALSE | X24: =AND(K24="",P24<>"Utility service",P24<>"Campaign services") -> FALSE | Y24: =AND(L24="",OR(P24="Merchandise replenishment",P24="Office supplies",P24="Transport and logistics")) -> FALSE | Z24: =OR(F24>Year_End_Window_End,AND(E24>=Year_End_Window_Start,F24>=Year_End_Window_Start)) -> FALSE
A25: INV-00021 | B25: V010 | C25: Thuraya Packaging | D25: 010-2025-0021 | E25: 45896 | F25: 45926 | G25: 45956 | H25: 11940.06 | I25: 1557.4 | J25: 10382.66 | K25: PO-00021 | L25: GR-00021 | M25: PAY-00021 | N25: 45956 | O25: Paid | P25: Office supplies | Q25: USR_NA | R25: USR_RE | S25: Pending | T25: Complete | U25: =F25-E25 -> 30 | V25: =H25>High_Value_AP_Threshold -> FALSE | W25: =COUNTIFS($B$5:$B$304,B25,$D$5:$D$304,D25)>1 -> FALSE | X25: =AND(K25="",P25<>"Utility service",P25<>"Campaign services") -> FALSE | Y25: =AND(L25="",OR(P25="Merchandise replenishment",P25="Office supplies",P25="Transport and logistics")) -> FALSE | Z25: =OR(F25>Year_End_Window_End,AND(E25>=Year_End_Window_Start,F25>=Year_End_Window_Start)) -> FALSE
A26: INV-00022 | B26: V002 | C26: Red Sand Facilities LLC | D26: 002-2025-0022 | E26: 45805 | F26: 45806 | G26: 45836 | H26: 60806.54 | I26: 7931.29 | J26: 52875.25 | K26: PO-00022 | O26: Pending | P26: Utility service | Q26: USR_AH | R26: USR_OM | S26: Approved | T26: Partial | U26: =F26-E26 -> 1 | V26: =H26>High_Value_AP_Threshold -> FALSE | W26: =COUNTIFS($B$5:$B$304,B26,$D$5:$D$304,D26)>1 -> FALSE | X26: =AND(K26="",P26<>"Utility service",P26<>"Campaign services") -> FALSE | Y26: =AND(L26="",OR(P26="Merchandise replenishment",P26="Office supplies",P26="Transport and logistics")) -> FALSE | Z26: =OR(F26>Year_End_Window_End,AND(E26>=Year_End_Window_Start,F26>=Year_End_Window_Start)) -> FALSE
A27: INV-00023 | B27: V006 | C27: Palm Office Supplies | D27: 006-2025-0023 | E27: 45923 | F27: 45923 | G27: 45953 | H27: 61534.08 | I27: 8026.18 | J27: 53507.9 | K27: PO-00023 | M27: PAY-00023 | N27: 45947 | O27: Paid | P27: Store maintenance | Q27: USR_AH | R27: USR_OM | S27: Approved | T27: Partial | U27: =F27-E27 -> 0 | V27: =H27>High_Value_AP_Threshold -> FALSE | W27: =COUNTIFS($B$5:$B$304,B27,$D$5:$D$304,D27)>1 -> FALSE | X27: =AND(K27="",P27<>"Utility service",P27<>"Campaign services") -> FALSE | Y27: =AND(L27="",OR(P27="Merchandise replenishment",P27="Office supplies",P27="Transport and logistics")) -> FALSE | Z27: =OR(F27>Year_End_Window_End,AND(E27>=Year_End_Window_Start,F27>=Year_End_Window_Start)) -> FALSE
A28: INV-00024 | B28: V002 | C28: Red Sand Facilities LLC | D28: 002-2025-0024 | E28: 46003 | F28: 46018 | G28: 46048 | H28: 1005.5 | I28: 131.15 | J28: 874.35 | K28: PO-00024 | O28: Pending | P28: Utility service | Q28: USR_SA | R28: USR_OM | S28: Pending | T28: Partial | U28: =F28-E28 -> 15 | V28: =H28>High_Value_AP_Threshold -> FALSE | W28: =COUNTIFS($B$5:$B$304,B28,$D$5:$D$304,D28)>1 -> FALSE | X28: =AND(K28="",P28<>"Utility service",P28<>"Campaign services") -> FALSE | Y28: =AND(L28="",OR(P28="Merchandise replenishment",P28="Office supplies",P28="Transport and logistics")) -> FALSE | Z28: =OR(F28>Year_End_Window_End,AND(E28>=Year_End_Window_Start,F28>=Year_End_Window_Start)) -> FALSE
A29: INV-00025 | B29: V001 | C29: Najd Merchandising Co. | D29: 001-2025-0025 | E29: 45813 | F29: 45818 | G29: 45848 | H29: 49387.47 | I29: 6441.84 | J29: 42945.63 | K29: PO-00025 | L29: GR-00025 | O29: Pending | P29: Merchandise replenishment | Q29: USR_RE | R29: USR_OM | S29: Approved | T29: Complete | U29: =F29-E29 -> 5 | V29: =H29>High_Value_AP_Threshold -> FALSE | W29: =COUNTIFS($B$5:$B$304,B29,$D$5:$D$304,D29)>1 -> FALSE | X29: =AND(K29="",P29<>"Utility service",P29<>"Campaign services") -> FALSE | Y29: =AND(L29="",OR(P29="Merchandise replenishment",P29="Office supplies",P29="Transport and logistics")) -> FALSE | Z29: =OR(F29>Year_End_Window_End,AND(E29>=Year_End_Window_Start,F29>=Year_End_Window_Start)) -> FALSE
A30: INV-00026 | B30: V003 | C30: Sahab IT Services | D30: 003-2025-0026 | E30: 45727 | F30: 45729 | G30: 45759 | H30: 46141.32 | I30: 6018.43 | J30: 40122.89 | K30: PO-00026 | O30: Pending | P30: Store maintenance | Q30: USR_AH | R30: USR_RE | S30: Approved | T30: Partial | U30: =F30-E30 -> 2 | V30: =H30>High_Value_AP_Threshold -> FALSE | W30: =COUNTIFS($B$5:$B$304,B30,$D$5:$D$304,D30)>1 -> FALSE | X30: =AND(K30="",P30<>"Utility service",P30<>"Campaign services") -> FALSE | Y30: =AND(L30="",OR(P30="Merchandise replenishment",P30="Office supplies",P30="Transport and logistics")) -> FALSE | Z30: =OR(F30>Year_End_Window_End,AND(E30>=Year_End_Window_Start,F30>=Year_End_Window_Start)) -> FALSE
A31: INV-00027 | B31: V008 | C31: Desert Star Maintenance | D31: 008-2025-0027 | E31: 45752 | F31: 45755 | G31: 45785 | H31: 18408.71 | I31: 2401.14 | J31: 16007.57 | K31: PO-00027 | L31: GR-00027 | M31: PAY-00027 | N31: 45777 | O31: Paid | P31: Transport and logistics | Q31: USR_FA | R31: USR_FA | S31: Approved | T31: Complete | U31: =F31-E31 -> 3 | V31: =H31>High_Value_AP_Threshold -> FALSE | W31: =COUNTIFS($B$5:$B$304,B31,$D$5:$D$304,D31)>1 -> FALSE | X31: =AND(K31="",P31<>"Utility service",P31<>"Campaign services") -> FALSE | Y31: =AND(L31="",OR(P31="Merchandise replenishment",P31="Office supplies",P31="Transport and logistics")) -> FALSE | Z31: =OR(F31>Year_End_Window_End,AND(E31>=Year_End_Window_Start,F31>=Year_End_Window_Start)) -> FALSE
A32: INV-00028 | B32: V005 | C32: Rimal Utilities Provider | D32: 005-2025-0028 | E32: 45780 | F32: 45780 | G32: 45810 | H32: 31846.87 | I32: 4153.94 | J32: 27692.93 | K32: PO-00028 | M32: PAY-00028 | N32: 45825 | O32: Paid | P32: Utility service | Q32: USR_SA | R32: USR_NA | S32: Approved | T32: Partial | U32: =F32-E32 -> 0 | V32: =H32>High_Value_AP_Threshold -> FALSE | W32: =COUNTIFS($B$5:$B$304,B32,$D$5:$D$304,D32)>1 -> FALSE | X32: =AND(K32="",P32<>"Utility service",P32<>"Campaign services") -> FALSE | Y32: =AND(L32="",OR(P32="Merchandise replenishment",P32="Office supplies",P32="Transport and logistics")) -> FALSE | Z32: =OR(F32>Year_End_Window_End,AND(E32>=Year_End_Window_Start,F32>=Year_End_Window_Start)) -> FALSE
A33: INV-00029 | B33: V009 | C33: Afaq Professional Services | D33: 009-2025-0029 | E33: 45720 | F33: 45727 | G33: 45757 | H33: 65281.66 | I33: 8515 | J33: 56766.66 | K33: PO-00029 | M33: PAY-00029 | N33: 45732 | O33: Paid | P33: Cloud support services | Q33: USR_AH | R33: USR_OM | S33: Approved | T33: Partial | U33: =F33-E33 -> 7 | V33: =H33>High_Value_AP_Threshold -> FALSE | W33: =COUNTIFS($B$5:$B$304,B33,$D$5:$D$304,D33)>1 -> FALSE | X33: =AND(K33="",P33<>"Utility service",P33<>"Campaign services") -> FALSE | Y33: =AND(L33="",OR(P33="Merchandise replenishment",P33="Office supplies",P33="Transport and logistics")) -> FALSE | Z33: =OR(F33>Year_End_Window_End,AND(E33>=Year_End_Window_Start,F33>=Year_End_Window_Start)) -> FALSE
A34: INV-00030 | B34: V004 | C34: Wadi Marketing Studio | D34: 004-2025-0030 | E34: 45838 | F34: 45840 | G34: 45870 | H34: 20681.74 | I34: 2697.62 | J34: 17984.12 | K34: PO-00030 | L34: GR-00030 | M34: PAY-00030 | N34: 45853 | O34: Paid | P34: Transport and logistics | Q34: USR_AH | R34: USR_NA | S34: Approved | T34: Complete | U34: =F34-E34 -> 2 | V34: =H34>High_Value_AP_Threshold -> FALSE | W34: =COUNTIFS($B$5:$B$304,B34,$D$5:$D$304,D34)>1 -> FALSE | X34: =AND(K34="",P34<>"Utility service",P34<>"Campaign services") -> FALSE | Y34: =AND(L34="",OR(P34="Merchandise replenishment",P34="Office supplies",P34="Transport and logistics")) -> FALSE | Z34: =OR(F34>Year_End_Window_End,AND(E34>=Year_End_Window_Start,F34>=Year_End_Window_Start)) -> FALSE
A35: INV-00031 | B35: V003 | C35: Sahab IT Services | D35: 003-2025-0031 | E35: 45767 | F35: 45769 | G35: 45799 | H35: 36719.14 | I35: 4789.45 | J35: 31929.69 | K35: PO-00031 | M35: PAY-00031 | N35: 45780 | O35: Paid | P35: Utility service | Q35: USR_RE | R35: USR_FA | S35: Approved | T35: Partial | U35: =F35-E35 -> 2 | V35: =H35>High_Value_AP_Threshold -> FALSE | W35: =COUNTIFS($B$5:$B$304,B35,$D$5:$D$304,D35)>1 -> FALSE | X35: =AND(K35="",P35<>"Utility service",P35<>"Campaign services") -> FALSE | Y35: =AND(L35="",OR(P35="Merchandise replenishment",P35="Office supplies",P35="Transport and logistics")) -> FALSE | Z35: =OR(F35>Year_End_Window_End,AND(E35>=Year_End_Window_Start,F35>=Year_End_Window_Start)) -> FALSE
A36: INV-00032 | B36: V009 | C36: Afaq Professional Services | D36: 009-2025-0032 | E36: 45736 | F36: 45737 | G36: 45767 | H36: 5662.91 | I36: 738.64 | J36: 4924.27 | K36: PO-00032 | M36: PAY-00032 | N36: 45782 | O36: Paid | P36: Cloud support services | Q36: USR_NA | R36: USR_NA | S36: Approved | T36: Partial | U36: =F36-E36 -> 1 | V36: =H36>High_Value_AP_Threshold -> FALSE | W36: =COUNTIFS($B$5:$B$304,B36,$D$5:$D$304,D36)>1 -> FALSE | X36: =AND(K36="",P36<>"Utility service",P36<>"Campaign services") -> FALSE | Y36: =AND(L36="",OR(P36="Merchandise replenishment",P36="Office supplies",P36="Transport and logistics")) -> FALSE | Z36: =OR(F36>Year_End_Window_End,AND(E36>=Year_End_Window_Start,F36>=Year_End_Window_Start)) -> FALSE
A37: INV-00033 | B37: V007 | C37: Oasis Logistics | D37: 007-2025-0033 | E37: 45912 | F37: 45915 | G37: 45945 | H37: 13251.66 | I37: 1728.48 | J37: 11523.18 | K37: PO-00033 | L37: GR-00033 | M37: PAY-00033 | N37: 45939 | O37: Paid | P37: Transport and logistics | Q37: USR_RE | R37: USR_NA | S37: Approved | T37: Complete | U37: =F37-E37 -> 3 | V37: =H37>High_Value_AP_Threshold -> FALSE | W37: =COUNTIFS($B$5:$B$304,B37,$D$5:$D$304,D37)>1 -> FALSE | X37: =AND(K37="",P37<>"Utility service",P37<>"Campaign services") -> FALSE | Y37: =AND(L37="",OR(P37="Merchandise replenishment",P37="Office supplies",P37="Transport and logistics")) -> FALSE | Z37: =OR(F37>Year_End_Window_End,AND(E37>=Year_End_Window_Start,F37>=Year_End_Window_Start)) -> FALSE
A38: INV-00034 | B38: V003 | C38: Sahab IT Services | D38: 003-2025-0034 | E38: 45948 | F38: 45963 | G38: 45993 | H38: 71587.32 | I38: 9337.48 | J38: 62249.84 | K38: PO-00034 | M38: PAY-00034 | N38: 45976 | O38: Paid | P38: Campaign services | Q38: USR_AH | R38: USR_NA | S38: Approved | T38: Partial | U38: =F38-E38 -> 15 | V38: =H38>High_Value_AP_Threshold -> FALSE | W38: =COUNTIFS($B$5:$B$304,B38,$D$5:$D$304,D38)>1 -> FALSE | X38: =AND(K38="",P38<>"Utility service",P38<>"Campaign services") -> FALSE | Y38: =AND(L38="",OR(P38="Merchandise replenishment",P38="Office supplies",P38="Transport and logistics")) -> FALSE | Z38: =OR(F38>Year_End_Window_End,AND(E38>=Year_End_Window_Start,F38>=Year_End_Window_Start)) -> FALSE
A39: INV-00035 | B39: V001 | C39: Najd Merchandising Co. | D39: 001-2025-0035 | E39: 45830 | F39: 45835 | G39: 45865 | H39: 67597 | I39: 8817 | J39: 58780 | K39: PO-00035 | M39: PAY-00035 | N39: 45870 | O39: Paid | P39: Store maintenance | Q39: USR_RE | R39: USR_RE | S39: Approved | T39: Partial | U39: =F39-E39 -> 5 | V39: =H39>High_Value_AP_Threshold -> FALSE | W39: =COUNTIFS($B$5:$B$304,B39,$D$5:$D$304,D39)>1 -> FALSE | X39: =AND(K39="",P39<>"Utility service",P39<>"Campaign services") -> FALSE | Y39: =AND(L39="",OR(P39="Merchandise replenishment",P39="Office supplies",P39="Transport and logistics")) -> FALSE | Z39: =OR(F39>Year_End_Window_End,AND(E39>=Year_End_Window_Start,F39>=Year_End_Window_Start)) -> FALSE
